Workbook

Sheet 01_Dashboard
A1: งาน Gift โรงเรียนไตรพัฒน์ — เงินกองกลาง
A2: Real-time Dashboard | ทีมการเงินเป็น Single Source of Truth | รายรับ 02_Income รายจ่าย 03_Expense คืนเงิน 08_Refund
A4: A. Financial Overview
A5: TOTAL INCOME | C5: TEAM REFUNDS | E5: TOTAL EXPENSE | G5: CURRENT BALANCE
A6: =SUM('02_Income'!F2:F1000) | C6: =SUM('08_Refund'!E2:E1000) | E6: =SUM('03_Expense'!F2:F1000) | G6: =A6+C6-E6
A8: B. Income by Source
A9: Source | B9: Amount
A10: PTA Contribution | B10: =SUMIF('02_Income'!C:C,A10,'02_Income'!F:F)
A11: Sponsorship | B11: =SUMIF('02_Income'!C:C,A11,'02_Income'!F:F)
A12: Workshop Revenue | B12: =SUMIF('02_Income'!C:C,A12,'02_Income'!F:F)
A13: Shop Revenue | B13: =SUMIF('02_Income'!C:C,A13,'02_Income'!F:F)
A14: Donations | B14: =SUMIF('02_Income'!C:C,A14,'02_Income'!F:F)
A15: Auction Proceeds | B15: =SUMIF('02_Income'!C:C,A15,'02_Income'!F:F)
A16: Other Income | B16: =SUMIF('02_Income'!C:C,A16,'02_Income'!F:F)
A17: TOTAL | B17: =SUM(B10:B16)
A19: C. Expense by Team | F19: D. Expense by Category
A20: Team | B20: Transferred | C20: Refunded | D20: Net Spent | F20: Category | G20: Amount
A21: Gift Team | B21: =SUMIF('03_Expense'!C:C,A21,'03_Expense'!F:F) | C21: =SUMIF('08_Refund'!C:C,A21,'08_Refund'!E:E) | D21: =B21-C21 | F21: Gifts | G21: =SUMIF('03_Expense'!D:D,F21,'03_Expense'!F:F)
A22: Shop Team | B22: =SUMIF('03_Expense'!C:C,A22,'03_Expense'!F:F) | C22: =SUMIF('08_Refund'!C:C,A22,'08_Refund'!E:E) | D22: =B22-C22 | F22: Materials | G22: =SUMIF('03_Expense'!D:D,F22,'03_Expense'!F:F)
A23: Venue & Safety Team | B23: =SUMIF('03_Expense'!C:C,A23,'03_Expense'!F:F) | C23: =SUMIF('08_Refund'!C:C,A23,'08_Refund'!E:E) | D23: =B23-C23 | F23: Venue | G23: =SUMIF('03_Expense'!D:D,F23,'03_Expense'!F:F)
A24: Public Relations Team | B24: =SUMIF('03_Expense'!C:C,A24,'03_Expense'!F:F) | C24: =SUMIF('08_Refund'!C:C,A24,'08_Refund'!E:E) | D24: =B24-C24 | F24: Equipment | G24: =SUMIF('03_Expense'!D:D,F24,'03_Expense'!F:F)
A25: Workshop Team | B25: =SUMIF('03_Expense'!C:C,A25,'03_Expense'!F:F) | C25: =SUMIF('08_Refund'!C:C,A25,'08_Refund'!E:E) | D25: =B25-C25 | F25: Safety | G25: =SUMIF('03_Expense'!D:D,F25,'03_Expense'!F:F)
A26: Activity Team | B26: =SUMIF('03_Expense'!C:C,A26,'03_Expense'!F:F) | C26: =SUMIF('08_Refund'!C:C,A26,'08_Refund'!E:E) | D26: =B26-C26 | F26: Marketing | G26: =SUMIF('03_Expense'!D:D,F26,'03_Expense'!F:F)
A27: TOTAL | B27: =SUM(B21:B26) | C27: =SUM(C21:C26) | D27: =SUM(D21:D26) | F27: Activities | G27: =SUMIF('03_Expense'!D:D,F27,'03_Expense'!F:F)
F28: Other | G28: =SUMIF('03_Expense'!D:D,F28,'03_Expense'!F:F)
F29: TOTAL | G29: =SUM(G21:G28)
A31: E. Recent Transactions
A32: Date | B32: Team / Source | C32: Description | D32: Amount
A33: 46257 | B33: Activity Team | C33: คืนเงินสดเหลือค่าขนส่งอุปกรณ์กิจกรรม | D33: 100
A34: 46256 | B34: Gift Team | C34: คืนเงินสดเหลือค่าของที่ระลึกผู้บริจาค | D34: 150
A35: 46255 | B35: Public Relations Team | C35: คืนเงินเหลือค่าพิมพ์โปสเตอร์ | D35: 200
A36: 46255 | B36: Shop Team | C36: คืนเงินเหลือค่าสินค้าบูธร้านค้า | D36: 400
A37: 46254 | B37: Workshop Team | C37: คืนเงินเหลือค่าวัสดุงานฝีมือ Workshop | D37: 300
A38: 46252 | B38: Workshop Revenue | C38: รายได้จาก Workshop สติมา Tea (ชาภาวนา) | D38: 2200
A39: 46251 | B39: Workshop Revenue | C39: รายได้จาก Workshop เย็บสมุด | D39: 1800
A40: 46250 | B40: Public Relations Team | C40: ค่าออกแบบสื่อออนไลน์ | D40: 500
A41: 46250 | B41: Shop Revenue | C41: รายได้จากบูธร้านค้างาน Gift | D41: 3500
A42: 46249 | B42: Shop Team | C42: ถุงกระดาษสำหรับขายของ | D42: 700
A44: ตารางนี้เป็นข้อมูลตัวอย่างให้เปิดด้วย Excel ได้ หลังอัปโหลด Google Sheets ให้รันเมนู งาน Gift Finance → สร้างชีตรายงาน เพื่อดึงรายการล่าสุดอัตโนมัติ
A45: วิธีใช้งาน
...

Sheet 02_Income
A1: Income ID | B1: Date | C1: Income Source | D1: Workshop Offerings | E1: Description | F1: Amount | G1: Evidence URL | H1: Recorded By | I1: Remark
A2: INC-0001 | B2: 46235 | C2: PTA Contribution | E2: เงินสนับสนุน PTA โรงเรียนไตรพัฒน์ สำหรับงาน Gift | F2: 25000 | G2: https://drive.google.com/file/d/mock-inc-0001/view | H2: คุณศิริพร | I2: เงินกองกลางตั้งต้นจาก PTA
A3: INC-0002 | B3: 46237 | C3: Sponsorship | E3: สปอนเซอร์งาน Gift จากร้านชุมชน ABC | F3: 8000 | G3: https://drive.google.com/file/d/mock-inc-0002/view | H3: คุณศิริพร
A4: INC-0003 | B4: 46239 | C4: Donations | E4: เงินบริจาคจากผู้ปกครอง | F4: 3000 | G4: https://drive.google.com/file/d/mock-inc-0003/view | H4: คุณศิริพร
A5: INC-0004 | B5: 46244 | C5: Workshop Revenue | D5: 1 | E5: รายได้จาก Workshop งานไม้ | F5: 4500 | G5: https://drive.google.com/file/d/mock-inc-0004/view | H5: คุณศิริพร
A6: INC-0005 | B6: 46246 | C6: Auction Proceeds | E6: รายได้จากการประมูลของที่ระลึก | F6: 6000 | G6: https://drive.google.com/file/d/mock-inc-0005/view | H6: คุณศิริพร
A7: INC-0006 | B7: 46249 | C7: Other Income | E7: รายได้อื่น ๆ จากบูธขายน้ำ | F7: 1200 | G7: https://drive.google.com/file/d/mock-inc-0006/view | H7: คุณศิริพร
A8: INC-0007 | B8: 46250 | C8: Shop Revenue | E8: รายได้จากบูธร้านค้างาน Gift | F8: 3500 | G8: https://drive.google.com/file/d/mock-inc-0007/view | H8: คุณศิริพร | I8: ยอดขายของที่ระลึกและสินค้าบูธ Shop Team
A9: INC-0008 | B9: 46251 | C9: Workshop Revenue | D9: 6 | E9: รายได้จาก Workshop เย็บสมุด | F9: 1800 | G9: https://drive.google.com/file/d/mock-inc-0008/view | H9: คุณศิริพร
A10: INC-0009 | B10: 46252 | C10: Workshop Revenue | D10: 12 | E10: รายได้จาก Workshop สติมา Tea (ชาภาวนา) | F10: 2200 | G10: https://drive.google.com/file/d/mock-inc-0009/view | H10: คุณณัฐชา

Sheet 03_Expense
A1: Payment ID | B1: Payment Date | C1: Team | D1: Expense Category | E1: Description | F1: Amount | G1: Recipient / Payee | H1: Payment Method | I1: Transfer Reference | J1: Evidence URL | K1: Recorded By | L1: Remark
A2: PAY-0001 | B2: 46239 | C2: Gift Team | D2: Gifts | E2: ซื้อของรางวัลงาน Gift | F2: 2500 | G2: นาย A | H2: Transfer | I2: TRF-20260805-001 | J2: https://drive.google.com/file/d/mock-pay-0001/view | K2: คุณศิริพร
A3: PAY-0002 | B3: 46240 | C3: Workshop Team | D3: Materials | E3: วัสดุงานฝีมือ Workshop | F3: 1800 | G3: ร้าน ABC Craft | H3: Transfer | I3: TRF-20260806-001 | J3: https://drive.google.com/file/d/mock-pay-0002/view | K3: คุณศิริพร
A4: PAY-0003 | B4: 46241 | C4: Venue & Safety Team | D4: Equipment | E4: เช่าเต็นท์สถานที่จัดงาน | F4: 8000 | G4: ร้าน XYZ Tent | H4: Transfer | I4: TRF-20260807-001 | J4: https://drive.google.com/file/d/mock-pay-0003/view | K4: คุณศิริพร | L4: ค่าเช่าเต็นท์หลักของงาน
A5: PAY-0004 | B5: 46242 | C5: Shop Team | D5: Materials | E5: ซื้อสินค้าสำหรับบูธร้านค้า | F5: 3200 | G5: ร้าน DEF | H5: Transfer | I5: TRF-20260808-001 | J5: https://drive.google.com/file/d/mock-pay-0004/view | K5: คุณศิริพร
A6: PAY-0005 | B6: 46243 | C6: Public Relations Team | D6: Marketing | E6: พิมพ์โปสเตอร์และใบปลิว | F6: 1500 | G6: โรงพิมพ์ GHI | H6: Transfer | I6: TRF-20260809-001 | J6: https://drive.google.com/file/d/mock-pay-0005/view | K6: คุณศิริพร
A7: PAY-0006 | B7: 46244 | C7: Activity Team | D7: Activities | E7: ค่าอุปกรณ์กิจกรรมเด็ก | F7: 2800 | G7: ร้าน JKL | H7: Transfer | I7: TRF-20260810-001 | J7: https://drive.google.com/file/d/mock-pay-0006/view | K7: คุณศิริพร
A8: PAY-0007 | B8: 46245 | C8: Venue & Safety Team | D8: Safety | E8: อุปกรณ์ความปลอดภัย | F8: 1200 | G8: ร้าน Safety Plus | H8: Transfer | I8: TRF-20260811-001 | J8: https://drive.google.com/file/d/mock-pay-0007/view | K8: คุณศิริพร
A9: PAY-0008 | B9: 46246 | C9: Workshop Team | D9: Materials | E9: วัสดุเพิ่มเติม Workshop | F9: 900 | G9: ร้าน ABC Craft | H9: Transfer | I9: TRF-20260812-001 | J9: https://drive.google.com/file/d/mock-pay-0008/view | K9: คุณศิริพร
A10: PAY-0009 | B10: 46247 | C10: Gift Team | D10: Gifts | E10: ของที่ระลึกผู้บริจาค | F10: 800 | G10: นางสาว B | H10: Transfer | I10: TRF-20260813-001 | J10: https://drive.google.com/file/d/mock-pay-0009/view | K10: คุณศิริพร
A11: PAY-0010 | B11: 46248 | C11: Activity Team | D11: Other | E11: ค่าขนส่งอุปกรณ์กิจกรรม | F11: 600 | G11: นาย C | H11: Cash | I11: CASH-001 | J11: https://drive.google.com/file/d/mock-pay-0010/view | K11: คุณศิริพร | L11: จ่ายสด ค่าขนส่งในวันจัดเตรียมงาน
A12: PAY-0011 | B12: 46249 | C12: Shop Team | D12: Other | E12: ถุงกระดาษสำหรับขายของ | F12: 700 | G12: ร้าน Packaging | H12: Transfer | I12: TRF-20260815-001 | J12: https://drive.google.com/file/d/mock-pay-0011/view | K12: คุณศิริพร
A13: PAY-0012 | B13: 46250 | C13: Public Relations Team | D13: Marketing | E13: ค่าออกแบบสื่อออนไลน์ | F13: 500 | G13: นาย D Designer | H13: PromptPay | I13: PP-20260816-001 | J13: https://drive.google.com/file/d/mock-pay-0012/view | K13: คุณศิริพร

Sheet 04_Team_Budget
A1: งบประมาณต่อทีม — งาน Gift โรงเรียนไตรพัฒน์
A2: Transferred จาก 03_Expense Refunded จาก 08_Refund Actual Paid = โอนแล้วหักคืน
A4: Team | B4: Budget Allocation | C4: Transferred | D4: Refunded | E4: Actual Paid | F4: Remaining | G4: % Used
A5: Gift Team | B5: 4000 | C5: =SUMIF('03_Expense'!C:C,A5,'03_Expense'!F:F) | D5: =SUMIF('08_Refund'!C:C,A5,'08_Refund'!E:E) | E5: =C5-D5 | F5: =B5-E5 | G5: =IF(B5=0,0,E5/B5)
A6: Shop Team | B6: 5000 | C6: =SUMIF('03_Expense'!C:C,A6,'03_Expense'!F:F) | D6: =SUMIF('08_Refund'!C:C,A6,'08_Refund'!E:E) | E6: =C6-D6 | F6: =B6-E6 | G6: =IF(B6=0,0,E6/B6)
A7: Venue & Safety Team | B7: 12000 | C7: =SUMIF('03_Expense'!C:C,A7,'03_Expense'!F:F) | D7: =SUMIF('08_Refund'!C:C,A7,'08_Refund'!E:E) | E7: =C7-D7 | F7: =B7-E7 | G7: =IF(B7=0,0,E7/B7)
A8: Public Relations Team | B8: 2500 | C8: =SUMIF('03_Expense'!C:C,A8,'03_Expense'!F:F) | D8: =SUMIF('08_Refund'!C:C,A8,'08_Refund'!E:E) | E8: =C8-D8 | F8: =B8-E8 | G8: =IF(B8=0,0,E8/B8)
A9: Workshop Team | B9: 4000 | C9: =SUMIF('03_Expense'!C:C,A9,'03_Expense'!F:F) | D9: =SUMIF('08_Refund'!C:C,A9,'08_Refund'!E:E) | E9: =C9-D9 | F9: =B9-E9 | G9: =IF(B9=0,0,E9/B9)
A10: Activity Team | B10: 5000 | C10: =SUMIF('03_Expense'!C:C,A10,'03_Expense'!F:F) | D10: =SUMIF('08_Refund'!C:C,A10,'08_Refund'!E:E) | E10: =C10-D10 | F10: =B10-E10 | G10: =IF(B10=0,0,E10/B10)
A11: TOTAL | B11: =SUM(B5:B10) | C11: =SUM(C5:C10) | D11: =SUM(D5:D10) | E11: =SUM(E5:E10) | F11: =SUM(F5:F10) | G11: =IF(B11=0,0,E11/B11)
A13: ถ้ายังไม่มีการกำหนด Budget ต่อทีม ให้เว้นคอลัมน์ Budget Allocation ไว้ แล้วยังใช้ Transferred / Refunded / Actual Paid ตอนปิดงานได้

Sheet 05_Master_Data
A1: Income Source | B1: Team | C1: Expense Category | D1: Payment Method | E1: Recorded By | F1: Workshop Offering ID | G1: Workshop Offering | I1: หมายเหตุ
A2: PTA Contribution | B2: Gift Team | C2: Gifts | D2: Transfer | E2: คุณศิริพร | F2: 1 | G2: งานไม้ | I2: ชีตนี้เป็นรายการหลัก (dropdown) สำหรับ 02_Income, 03_Expense และ 08_Refund Workshop Offerings อยู่ภายใต้ Workshop Revenue คอลัมน์ F คือ ID ที่บันทึกลง 02_Income คอลัมน์ G คือชื่อที่แสดงในฟอร์ม อย่าลบค่าในรายการถ้ายังมีธุรกรรมที่อ้างอิงอยู่
A3: Sponsorship | B3: Shop Team | C3: Materials | D3: PromptPay | E3: คุณณัฐชา | F3: 2 | G3: well being: singing bowl, ขันธ์ธิเบต, ice bathing, mobility
A4: Workshop Revenue | B4: Venue & Safety Team | C4: Venue | D4: Cash | F4: 3 | G4: ถ่ายรูปเบื้องต้น
A5: Shop Revenue | B5: Public Relations Team | C5: Equipment | D5: Cheque | F5: 4 | G5: ศิลปะ, basic drawing, chalk board painting
A6: Donations | B6: Workshop Team | C6: Safety | F6: 5 | G6: Finance for non finance, Financial literacy
A7: Auction Proceeds | B7: Activity Team | C7: Marketing | F7: 6 | G7: เย็บสมุด
A8: Other Income | C8: Activities | F8: 7 | G8: จัดดอกไม้
C9: Other | F9: 8 | G9: ปักผ้า, Crochet, knitting
F10: 9 | G10: personal color
F11: 10 | G11: ยูริทมี
F12: 11 | G12: Enneagram Board Game นพลักษณ์
F13: 12 | G13: สติมา Tea (ชาภาวนา)
F14: 13 | G14: เย็บตุ๊กตา
F15: 14 | G15: Crafting music of life (together)
F16: 15 | G16: Beeswax wrap
F17: 16 | G17: ถักสร้อยหิน
F18: 17 | G18: Wet felting
F19: 18 | G19: Singing circle & community music gathering by Sound & Soul
F20: 19 | G20: กิจกรรม give back to nature/community

Sheet 06_Income_Report
A1: รายงานรายรับ — งาน Gift โรงเรียนไตรพัฒน์
A2: ข้อมูลตัวอย่างเรียงรหัสล่าสุดขึ้นก่อน คลิก 📄 เพื่อเปิดสลิป | ใน Google Sheets รันเมนูสร้างชีตรายงานเพื่อดึงข้อมูลสด
A4: Income ID | B4: Date | C4: Income Source | D4: Workshop Offerings | E4: Description | F4: Amount | G4: Evidence URL | H4: Recorded By | I4: Remark
A5: INC-0009 | B5: 46252 | C5: Workshop Revenue | D5: 12 | E5: รายได้จาก Workshop สติมา Tea (ชาภาวนา) | F5: 2200 | G5: 📄 | H5: คุณณัฐชา
A6: INC-0008 | B6: 46251 | C6: Workshop Revenue | D6: 6 | E6: รายได้จาก Workshop เย็บสมุด | F6: 1800 | G6: 📄 | H6: คุณศิริพร
A7: INC-0007 | B7: 46250 | C7: Shop Revenue | E7: รายได้จากบูธร้านค้างาน Gift | F7: 3500 | G7: 📄 | H7: คุณศิริพร | I7: ยอดขายของที่ระลึกและสินค้าบูธ Shop Team
A8: INC-0006 | B8: 46249 | C8: Other Income | E8: รายได้อื่น ๆ จากบูธขายน้ำ | F8: 1200 | G8: 📄 | H8: คุณศิริพร
A9: INC-0005 | B9: 46246 | C9: Auction Proceeds | E9: รายได้จากการประมูลของที่ระลึก | F9: 6000 | G9: 📄 | H9: คุณศิริพร
A10: INC-0004 | B10: 46244 | C10: Workshop Revenue | D10: 1 | E10: รายได้จาก Workshop งานไม้ | F10: 4500 | G10: 📄 | H10: คุณศิริพร
A11: INC-0003 | B11: 46239 | C11: Donations | E11: เงินบริจาคจากผู้ปกครอง | F11: 3000 | G11: 📄 | H11: คุณศิริพร
A12: INC-0002 | B12: 46237 | C12: Sponsorship | E12: สปอนเซอร์งาน Gift จากร้านชุมชน ABC | F12: 8000 | G12: 📄 | H12: คุณศิริพร
A13: INC-0001 | B13: 46235 | C13: PTA Contribution | E13: เงินสนับสนุน PTA โรงเรียนไตรพัฒน์ สำหรับงาน Gift | F13: 25000 | G13: 📄 | H13: คุณศิริพร | I13: เงินกองกลางตั้งต้นจาก PTA

Sheet 07_Expense_Report
A1: รายงานรายจ่าย — งาน Gift โรงเรียนไตรพัฒน์
A2: ข้อมูลตัวอย่างเรียงรหัสล่าสุดขึ้นก่อน คลิก 📄 เพื่อเปิดสลิป | ใน Google Sheets รันเมนูสร้างชีตรายงานเพื่อดึงข้อมูลสด
A4: Payment ID | B4: Payment Date | C4: Team | D4: Expense Category | E4: Description | F4: Amount | G4: Recipient / Payee | H4: Payment Method | I4: Evidence URL | J4: Recorded By | K4: Remark
A5: PAY-0012 | B5: 46250 | C5: Public Relations Team | D5: Marketing | E5: ค่าออกแบบสื่อออนไลน์ | F5: 500 | G5: นาย D Designer | H5: PromptPay | I5: 📄 | J5: คุณศิริพร
A6: PAY-0011 | B6: 46249 | C6: Shop Team | D6: Other | E6: ถุงกระดาษสำหรับขายของ | F6: 700 | G6: ร้าน Packaging | H6: Transfer | I6: 📄 | J6: คุณศิริพร
A7: PAY-0010 | B7: 46248 | C7: Activity Team | D7: Other | E7: ค่าขนส่งอุปกรณ์กิจกรรม | F7: 600 | G7: นาย C | H7: Cash | I7: 📄 | J7: คุณศิริพร | K7: จ่ายสด ค่าขนส่งในวันจัดเตรียมงาน
A8: PAY-0009 | B8: 46247 | C8: Gift Team | D8: Gifts | E8: ของที่ระลึกผู้บริจาค | F8: 800 | G8: นางสาว B | H8: Transfer | I8: 📄 | J8: คุณศิริพร
A9: PAY-0008 | B9: 46246 | C9: Workshop Team | D9: Materials | E9: วัสดุเพิ่มเติม Workshop | F9: 900 | G9: ร้าน ABC Craft | H9: Transfer | I9: 📄 | J9: คุณศิริพร
A10: PAY-0007 | B10: 46245 | C10: Venue & Safety Team | D10: Safety | E10: อุปกรณ์ความปลอดภัย | F10: 1200 | G10: ร้าน Safety Plus | H10: Transfer | I10: 📄 | J10: คุณศิริพร
A11: PAY-0006 | B11: 46244 | C11: Activity Team | D11: Activities | E11: ค่าอุปกรณ์กิจกรรมเด็ก | F11: 2800 | G11: ร้าน JKL | H11: Transfer | I11: 📄 | J11: คุณศิริพร
A12: PAY-0005 | B12: 46243 | C12: Public Relations Team | D12: Marketing | E12: พิมพ์โปสเตอร์และใบปลิว | F12: 1500 | G12: โรงพิมพ์ GHI | H12: Transfer | I12: 📄 | J12: คุณศิริพร
A13: PAY-0004 | B13: 46242 | C13: Shop Team | D13: Materials | E13: ซื้อสินค้าสำหรับบูธร้านค้า | F13: 3200 | G13: ร้าน DEF | H13: Transfer | I13: 📄 | J13: คุณศิริพร
A14: PAY-0003 | B14: 46241 | C14: Venue & Safety Team | D14: Equipment | E14: เช่าเต็นท์สถานที่จัดงาน | F14: 8000 | G14: ร้าน XYZ Tent | H14: Transfer | I14: 📄 | J14: คุณศิริพร | K14: ค่าเช่าเต็นท์หลักของงาน
A15: PAY-0002 | B15: 46240 | C15: Workshop Team | D15: Materials | E15: วัสดุงานฝีมือ Workshop | F15: 1800 | G15: ร้าน ABC Craft | H15: Transfer | I15: 📄 | J15: คุณศิริพร
A16: PAY-0001 | B16: 46239 | C16: Gift Team | D16: Gifts | E16: ซื้อของรางวัลงาน Gift | F16: 2500 | G16: นาย A | H16: Transfer | I16: 📄 | J16: คุณศิริพร

Sheet 08_Refund
A1: Refund ID | B1: Refund Date | C1: Team | D1: Related Payment ID | E1: Amount | F1: Refund Method | G1: Description | H1: Evidence URL | I1: Recorded By | J1: Remark
A2: REF-0001 | B2: 46254 | C2: Workshop Team | D2: PAY-0002 | E2: 300 | F2: Transfer | G2: คืนเงินเหลือค่าวัสดุงานฝีมือ Workshop | H2: https://drive.google.com/file/d/mock-ref-0001/view | I2: คุณศิริพร | J2: โอนเดิม 1,800 ใช้จริง 1,500
A3: REF-0002 | B3: 46255 | C3: Shop Team | D3: PAY-0004 | E3: 400 | F3: Transfer | G3: คืนเงินเหลือค่าสินค้าบูธร้านค้า | H3: https://drive.google.com/file/d/mock-ref-0002/view | I3: คุณศิริพร | J3: โอนเดิม 3,200 ใช้จริง 2,800
A4: REF-0003 | B4: 46255 | C4: Public Relations Team | D4: PAY-0005 | E4: 200 | F4: PromptPay | G4: คืนเงินเหลือค่าพิมพ์โปสเตอร์ | H4: https://drive.google.com/file/d/mock-ref-0003/view | I4: คุณณัฐชา | J4: โอนเดิม 1,500 ใช้จริง 1,300
A5: REF-0004 | B5: 46256 | C5: Gift Team | D5: PAY-0009 | E5: 150 | F5: Cash | G5: คืนเงินสดเหลือค่าของที่ระลึกผู้บริจาค | I5: คุณศิริพร | J5: โอนเดิม 800 ใช้จริง 650 — ไม่ได้แนบสลิปเพราะรับเงินสด
A6: REF-0005 | B6: 46257 | C6: Activity Team | D6: PAY-0010 | E6: 100 | F6: Cash | G6: คืนเงินสดเหลือค่าขนส่งอุปกรณ์กิจกรรม | H6: https://drive.google.com/file/d/mock-ref-0005/view | I6: คุณณัฐชา | J6: จ่ายสดเดิม 600 ใช้จริง 500

Sheet 09_Refund_Report
A1: รายงานคืนเงิน — งาน Gift โรงเรียนไตรพัฒน์
A2: ข้อมูลตัวอย่างเรียงรหัสล่าสุดขึ้นก่อน คลิก 📄 เพื่อเปิดสลิป | ใน Google Sheets รันเมนูสร้างชีตรายงานเพื่อดึงข้อมูลสด
A4: Refund ID | B4: Refund Date | C4: Team | D4: Related Payment ID | E4: Amount | F4: Refund Method | G4: Description | H4: Evidence URL | I4: Recorded By | J4: Remark
A5: REF-0005 | B5: 46257 | C5: Activity Team | D5: PAY-0010 | E5: 100 | F5: Cash | G5: คืนเงินสดเหลือค่าขนส่งอุปกรณ์กิจกรรม | H5: 📄 | I5: คุณณัฐชา | J5: จ่ายสดเดิม 600 ใช้จริง 500
A6: REF-0004 | B6: 46256 | C6: Gift Team | D6: PAY-0009 | E6: 150 | F6: Cash | G6: คืนเงินสดเหลือค่าของที่ระลึกผู้บริจาค | I6: คุณศิริพร | J6: โอนเดิม 800 ใช้จริง 650 — ไม่ได้แนบสลิปเพราะรับเงินสด
A7: REF-0003 | B7: 46255 | C7: Public Relations Team | D7: PAY-0005 | E7: 200 | F7: PromptPay | G7: คืนเงินเหลือค่าพิมพ์โปสเตอร์ | H7: 📄 | I7: คุณณัฐชา | J7: โอนเดิม 1,500 ใช้จริง 1,300
A8: REF-0002 | B8: 46255 | C8: Shop Team | D8: PAY-0004 | E8: 400 | F8: Transfer | G8: คืนเงินเหลือค่าสินค้าบูธร้านค้า | H8: 📄 | I8: คุณศิริพร | J8: โอนเดิม 3,200 ใช้จริง 2,800
A9: REF-0001 | B9: 46254 | C9: Workshop Team | D9: PAY-0002 | E9: 300 | F9: Transfer | G9: คืนเงินเหลือค่าวัสดุงานฝีมือ Workshop | H9: 📄 | I9: คุณศิริพร | J9: โอนเดิม 1,800 ใช้จริง 1,500
